<?xml version="1.0" encoding="utf-8"?>
<!-- This URDF was automatically created by SolidWorks to URDF Exporter! Originally created by Stephen Brawner (brawner@gmail.com) 
     Commit Version: 1.6.0-1-g15f4949  Build Version: 1.6.7594.29634
     For more information, please see http://wiki.ros.org/sw_urdf_exporter -->
<robot
  name="dummy_ros2">
  <link
    name="Base_Link">
    <inertial>
      <origin
        xyz="0.0234579864342645 4.16138602459676E-05 0.0148797662531894"
        rpy="0 0 0" />
      <mass
        value="7.42986278180058" />
      <inertia
        ixx="0.0180152527135656"
        ixy="-1.47598604288587E-06"
        ixz="7.85324242378633E-06"
        iyy="0.0174543464639099"
        iyz="-1.86487908268324E-06"
        izz="0.0326261531558901" />
    </inertial>
    <visual>
      <origin
        xyz="0 0 0"
        rpy="0 0 0" />
      <geometry>
        <mesh
          filename="package://dummy_py_ros2/meshes/Base_Link.STL" />
      </geometry>
      <material
        name="">
        <color
          rgba="0.752941176470588 0.752941176470588 0.752941176470588 1" />
      </material>
    </visual>
    <collision>
      <origin
        xyz="0 0 0"
        rpy="0 0 0" />
      <geometry>
        <mesh
          filename="package://dummy_py_ros2/meshes/Base_Link.STL" />
      </geometry>
    </collision>
  </link>
  <link
    name="Link1">
    <inertial>
      <origin
        xyz="0.00955411921483431 -0.00972117303858949 0.0173362747949995"
        rpy="0 0 0" />
      <mass
        value="0.415906699107813" />
      <inertia
        ixx="0.000192728972418038"
        ixy="8.05473407384544E-05"
        ixz="-7.04335001621821E-05"
        iyy="0.000237256162569907"
        iyz="4.5128264830821E-05"
        izz="0.000291498728900993" />
    </inertial>
    <visual>
      <origin
        xyz="0 0 0"
        rpy="0 0 0" />
      <geometry>
        <mesh
          filename="package://dummy_py_ros2/meshes/Link1.STL" />
      </geometry>
      <material
        name="">
        <color
          rgba="0.752941176470588 0.752941176470588 0.752941176470588 1" />
      </material>
    </visual>
    <collision>
      <origin
        xyz="0 0 0"
        rpy="0 0 0" />
      <geometry>
        <mesh
          filename="package://dummy_py_ros2/meshes/Link1.STL" />
      </geometry>
    </collision>
  </link>
  <joint
    name="Joint1"
    type="revolute">
    <origin
      xyz="0 0 0.0869999999999127"
      rpy="0 0 0" />
    <parent
      link="Base_Link" />
    <child
      link="Link1" />
    <axis
      xyz="0 0 1" />
    <limit
      lower="-3.14"
      upper="3.14"
      effort="100"
      velocity="1.0" />
  </joint>
  <link
    name="Link2">
    <inertial>
      <origin
        xyz="-0.000110586377565902 0.0728147333851237 -0.00074324600246801"
        rpy="0 0 0" />
      <mass
        value="2.46172843734832" />
      <inertia
        ixx="0.00254164147605489"
        ixy="1.8244584495965E-05"
        ixz="-3.05216672082952E-06"
        iyy="0.000666997424184514"
        iyz="0.000495528512907501"
        izz="0.00268029807187437" />
    </inertial>
    <visual>
      <origin
        xyz="0 0 0"
        rpy="0 0 0" />
      <geometry>
        <mesh
          filename="package://dummy_py_ros2/meshes/Link2.STL" />
      </geometry>
      <material
        name="">
        <color
          rgba="0.752941176470588 0.752941176470588 0.752941176470588 1" />
      </material>
    </visual>
    <collision>
      <origin
        xyz="0 0 0"
        rpy="0 0 0" />
      <geometry>
        <mesh
          filename="package://dummy_py_ros2/meshes/Link2.STL" />
      </geometry>
    </collision>
  </link>
  <joint
    name="Joint2"
    type="revolute">
    <origin
      xyz="0.0349999999999998 0 0.0375000000000872"
      rpy="1.5707963267949 0 -3.14159265358979" />
    <parent
      link="Link1" />
    <child
      link="Link2" />
    <axis
      xyz="0 0 1" />
    <limit
      lower="-3.14"
      upper="3.14"
      effort="100"
      velocity="1.0" />
  </joint>
  <link
    name="Link3">
    <inertial>
      <origin
        xyz="0.0452337573705155 -0.0146862138541927 0.00404107840790664"
        rpy="0 0 0" />
      <mass
        value="0.976841195302199" />
      <inertia
        ixx="0.000213598941033949"
        ixy="-5.08647076723867E-06"
        ixz="7.48442219571293E-05"
        iyy="0.00045137580489978"
        iyz="2.69568387765728E-06"
        izz="0.00033322121750123" />
    </inertial>
    <visual>
      <origin
        xyz="0 0 0"
        rpy="0 0 0" />
      <geometry>
        <mesh
          filename="package://dummy_py_ros2/meshes/Link3.STL" />
      </geometry>
      <material
        name="">
        <color
          rgba="0.752941176470588 0.752941176470588 0.752941176470588 1" />
      </material>
    </visual>
    <collision>
      <origin
        xyz="0 0 0"
        rpy="0 0 0" />
      <geometry>
        <mesh
          filename="package://dummy_py_ros2/meshes/Link3.STL" />
      </geometry>
    </collision>
  </link>
  <joint
    name="Joint3"
    type="revolute">
    <origin
      xyz="0 0.146 0"
      rpy="0 0 1.5707963267949" />
    <parent
      link="Link2" />
    <child
      link="Link3" />
    <axis
      xyz="0 0 1" />
    <limit
      lower="-3.14"
      upper="3.14"
      effort="100"
      velocity="1.0" />
  </joint>
  <link
    name="Link4">
    <inertial>
      <origin
        xyz="3.19413715008376E-05 -0.00188197668693867 0.0744253657804669"
        rpy="0 0 0" />
      <mass
        value="0.781860892466404" />
      <inertia
        ixx="0.000312775868862146"
        ixy="2.88922858791668E-09"
        ixz="-1.13047794806504E-07"
        iyy="0.00036955388052533"
        iyz="-2.25637508480122E-05"
        izz="0.000100456723216079" />
    </inertial>
    <visual>
      <origin
        xyz="0 0 0"
        rpy="0 0 0" />
      <geometry>
        <mesh
          filename="package://dummy_py_ros2/meshes/Link4.STL" />
      </geometry>
      <material
        name="">
        <color
          rgba="0.752941176470588 0.752941176470588 0.752941176470588 1" />
      </material>
    </visual>
    <collision>
      <origin
        xyz="0 0 0"
        rpy="0 0 0" />
      <geometry>
        <mesh
          filename="package://dummy_py_ros2/meshes/Link4.STL" />
      </geometry>
    </collision>
  </link>
  <joint
    name="Joint4"
    type="revolute">
    <origin
      xyz="0.052 0 0"
      rpy="-1.5707963267949 0 0" />
    <parent
      link="Link3" />
    <child
      link="Link4" />
    <axis
      xyz="0 0 1" />
    <limit
      lower="-3.14"
      upper="3.14"
      effort="100"
      velocity="1.0" />
  </joint>
  <link
    name="Link5">
    <inertial>
      <origin
        xyz="6.32659218006704E-05 0.0378393520721391 -0.0065387947525705"
        rpy="0 0 0" />
      <mass
        value="0.393021924463493" />
      <inertia
        ixx="0.000148490539597373"
        ixy="-3.66157118041582E-10"
        ixz="2.21226212112064E-07"
        iyy="8.52360544646063E-05"
        iyz="-2.51177165202851E-05"
        izz="0.000144262447135981" />
    </inertial>
    <visual>
      <origin
        xyz="0 0 0"
        rpy="0 0 0" />
      <geometry>
        <mesh
          filename="package://dummy_py_ros2/meshes/Link5.STL" />
      </geometry>
      <material
        name="">
        <color
          rgba="0.752941176470588 0.752941176470588 0.752941176470588 1" />
      </material>
    </visual>
    <collision>
      <origin
        xyz="0 0 0"
        rpy="0 0 0" />
      <geometry>
        <mesh
          filename="package://dummy_py_ros2/meshes/Link5.STL" />
      </geometry>
    </collision>
  </link>
  <joint
    name="Joint5"
    type="revolute">
    <origin
      xyz="0 0 0.116999999999999"
      rpy="1.5707963267949 0 0" />
    <parent
      link="Link4" />
    <child
      link="Link5" />
    <axis
      xyz="0 0 1" />
    <limit
      lower="-3.14"
      upper="3.14"
      effort="100"
      velocity="1.0" />
  </joint>
  <link
    name="Link6">
    <inertial>
      <origin
        xyz="-2.7756E-17 1.9082E-17 0.0075"
        rpy="0 0 0" />
      <mass
        value="0.1062" />
      <inertia
        ixx="1.5611E-05"
        ixy="3.6476E-21"
        ixz="-1.3408E-21"
        iyy="1.5611E-05"
        iyz="-2.1675E-21"
        izz="2.7258E-05" />
    </inertial>
    <visual>
      <origin
        xyz="0 0 0"
        rpy="0 0 0" />
      <geometry>
        <mesh
          filename="package://dummy_py_ros2/meshes/Link6.STL" />
      </geometry>
      <material
        name="">
        <color
          rgba="0.52941 0.54902 0.54902 1" />
      </material>
    </visual>
    <collision>
      <origin
        xyz="0 0 0"
        rpy="0 0 0" />
      <geometry>
        <mesh
          filename="package://dummy_py_ros2/meshes/Link6.STL" />
      </geometry>
    </collision>
  </link>
  <joint
    name="Joint6"
    type="revolute">
    <origin
      xyz="0 0.0625 0"
      rpy="-1.5708 0 0" />
    <parent
      link="Link5" />
    <child
      link="Link6" />
    <axis
      xyz="0 0 -1" />
    <limit
      lower="-3.14"
      upper="3.14"
      effort="100"
      velocity="1.0" />
  </joint>

  <!-- Gazebo colors (Gazebo ignores URDF <material> tags, must use <gazebo> tags) -->
  <gazebo reference="Base_Link">
    <material>Gazebo/Grey</material>
  </gazebo>
  <gazebo reference="Link1">
    <material>Gazebo/Grey</material>
  </gazebo>
  <gazebo reference="Link2">
    <material>Gazebo/Grey</material>
  </gazebo>
  <gazebo reference="Link3">
    <material>Gazebo/Grey</material>
  </gazebo>
  <gazebo reference="Link4">
    <material>Gazebo/Grey</material>
  </gazebo>
  <gazebo reference="Link5">
    <material>Gazebo/Grey</material>
  </gazebo>
  <gazebo reference="Link6">
    <material>Gazebo/DarkGrey</material>
  </gazebo>

</robot>